2025-09-30 20:26:32 - __main__ - INFO - cli.py:31 - main - Starting Odin CLI
2025-09-30 20:26:32 - infrastructure - INFO - cli.py:32 - main - Odin CLI initialized
2025-09-30 20:26:36 - __main__ - INFO - cli.py:31 - main - Starting Odin CLI
2025-09-30 20:26:36 - infrastructure - INFO - cli.py:32 - main - Odin CLI initialized
2025-09-30 20:26:36 - __main__ - ERROR - cli.py:147 - main - Configuration file not found: odin.yaml
2025-09-30 20:26:40 - __main__ - INFO - cli.py:31 - main - Starting Odin CLI
2025-09-30 20:26:40 - infrastructure - INFO - cli.py:32 - main - Odin CLI initialized
2025-09-30 20:26:51 - __main__ - INFO - cli.py:31 - main - Starting Odin CLI
2025-09-30 20:26:51 - infrastructure - INFO - cli.py:32 - main - Odin CLI initialized
2025-09-30 20:26:59 - __main__ - INFO - cli.py:31 - main - Starting Odin CLI
2025-09-30 20:26:59 - infrastructure - INFO - cli.py:32 - main - Odin CLI initialized
2025-09-30 20:27:08 - __main__ - INFO - cli.py:31 - main - Starting Odin CLI
2025-09-30 20:27:08 - infrastructure - INFO - cli.py:32 - main - Odin CLI initialized
2025-09-30 20:27:18 - __main__ - INFO - cli.py:31 - main - Starting Odin CLI
2025-09-30 20:27:18 - infrastructure - INFO - cli.py:32 - main - Odin CLI initialized
2025-09-30 20:27:29 - __main__ - INFO - cli.py:31 - main - Starting Odin CLI
2025-09-30 20:27:29 - infrastructure - INFO - cli.py:32 - main - Odin CLI initialized
2025-09-30 20:27:29 - infrastructure - INFO - cli.py:212 - handle_infrastructure_command - Checking infrastructure status
2025-09-30 20:27:30 - infrastructure - INFO - cli.py:215 - handle_infrastructure_command - Infrastructure status: {'docker': {'status': 'error', 'error': "'NoneType' object has no attribute 'containers'"}, 'localstack': {'status': 'error', 'error': "HTTPConnectionPool(host='localhost', port=4566): Max retries exceeded with url: /health (Caused by NewConnectionError('<urllib3.connection.HTTPConnection object at 0x7dc3853dee40>: Failed to establish a new connection: [Errno 111] Connection refused'))"}, 'minio': {'status': 'error', 'error': "HTTPConnectionPool(host='localhost', port=9000): Max retries exceeded with url: /minio/health/live (Caused by NewConnectionError('<urllib3.connection.HTTPConnection object at 0x7dc38542a490>: Failed to establish a new connection: [Errno 111] Connection refused'))"}, 'redis': {'status': 'error', 'error': 'Error 111 connecting to localhost:6379. Connection refused.'}, 'postgres': {'status': 'error', 'error': "No module named 'psycopg2'"}}
2025-09-30 20:35:44 - __main__ - INFO - cli.py:31 - main - Starting Odin CLI
2025-09-30 20:35:44 - infrastructure - INFO - cli.py:32 - main - Odin CLI initialized
2025-09-30 20:35:44 - infrastructure - INFO - cli.py:212 - handle_infrastructure_command - Checking infrastructure status
2025-09-30 20:35:44 - infrastructure - INFO - cli.py:215 - handle_infrastructure_command - Infrastructure status: {'docker': {'status': 'error', 'error': "'NoneType' object has no attribute 'containers'"}, 'localstack': {'status': 'error', 'error': "HTTPConnectionPool(host='localhost', port=4566): Max retries exceeded with url: /health (Caused by NewConnectionError('<urllib3.connection.HTTPConnection object at 0x7b310e5af4d0>: Failed to establish a new connection: [Errno 111] Connection refused'))"}, 'minio': {'status': 'running', 'endpoint': 'http://localhost:9000'}, 'redis': {'status': 'running', 'url': 'redis://localhost:6379'}, 'postgres': {'status': 'error', 'error': "No module named 'psycopg2'"}}
2025-09-30 20:36:16 - __main__ - INFO - cli.py:31 - main - Starting Odin CLI
2025-09-30 20:36:16 - infrastructure - INFO - cli.py:32 - main - Odin CLI initialized
2025-09-30 20:36:16 - infrastructure - INFO - cli.py:212 - handle_infrastructure_command - Checking infrastructure status
2025-09-30 20:36:17 - infrastructure - INFO - cli.py:215 - handle_infrastructure_command - Infrastructure status: {'docker': {'status': 'error', 'error': "'NoneType' object has no attribute 'containers'"}, 'localstack': {'status': 'error', 'error': "HTTPConnectionPool(host='localhost', port=4566): Max retries exceeded with url: /health (Caused by NewConnectionError('<urllib3.connection.HTTPConnection object at 0x7412b890ee40>: Failed to establish a new connection: [Errno 111] Connection refused'))"}, 'minio': {'status': 'running', 'endpoint': 'http://localhost:9000'}, 'redis': {'status': 'running', 'url': 'redis://localhost:6379'}, 'postgres': {'status': 'running', 'url': 'postgresql://wildlife:wildlife123@localhost:5432/wildlife'}}
2025-09-30 20:39:44 - __main__ - INFO - cli.py:31 - main - Starting Odin CLI
2025-09-30 20:39:44 - infrastructure - INFO - cli.py:32 - main - Odin CLI initialized
2025-09-30 20:39:44 - infrastructure - INFO - cli.py:212 - handle_infrastructure_command - Checking infrastructure status
2025-09-30 20:39:44 - infrastructure - INFO - cli.py:215 - handle_infrastructure_command - Infrastructure status: {'docker': {'status': 'error', 'error': "'NoneType' object has no attribute 'containers'"}, 'localstack': {'status': 'error', 'error': "HTTPConnectionPool(host='localhost', port=4566): Max retries exceeded with url: /health (Caused by NewConnectionError('<urllib3.connection.HTTPConnection object at 0x7de3361f2e40>: Failed to establish a new connection: [Errno 111] Connection refused'))"}, 'minio': {'status': 'error', 'error': "HTTPConnectionPool(host='localhost', port=9000): Max retries exceeded with url: /minio/health/live (Caused by NewConnectionError('<urllib3.connection.HTTPConnection object at 0x7de336246350>: Failed to establish a new connection: [Errno 111] Connection refused'))"}, 'redis': {'status': 'error', 'error': 'Error 111 connecting to localhost:6379. Connection refused.'}, 'postgres': {'status': 'error', 'error': 'connection to server at "localhost" (127.0.0.1), port 5432 failed: Connection refused\n\tIs the server running on that host and accepting TCP/IP connections?\n'}}
2025-09-30 20:41:15 - __main__ - INFO - cli.py:31 - main - Starting Odin CLI
2025-09-30 20:41:15 - infrastructure - INFO - cli.py:32 - main - Odin CLI initialized
2025-09-30 20:41:15 - infrastructure - INFO - cli.py:212 - handle_infrastructure_command - Checking infrastructure status
2025-09-30 20:41:15 - infrastructure - INFO - cli.py:215 - handle_infrastructure_command - Infrastructure status: {'docker': {'status': 'error', 'error': "'NoneType' object has no attribute 'containers'"}, 'localstack': {'status': 'error', 'error': "HTTPConnectionPool(host='localhost', port=4566): Max retries exceeded with url: /health (Caused by NewConnectionError('<urllib3.connection.HTTPConnection object at 0x739f107bee40>: Failed to establish a new connection: [Errno 111] Connection refused'))"}, 'minio': {'status': 'error', 'error': "HTTPConnectionPool(host='localhost', port=9000): Max retries exceeded with url: /minio/health/live (Caused by NewConnectionError('<urllib3.connection.HTTPConnection object at 0x739f10812350>: Failed to establish a new connection: [Errno 111] Connection refused'))"}, 'redis': {'status': 'error', 'error': 'Error 111 connecting to localhost:6379. Connection refused.'}, 'postgres': {'status': 'error', 'error': 'connection to server at "localhost" (127.0.0.1), port 5432 failed: Connection refused\n\tIs the server running on that host and accepting TCP/IP connections?\n'}}
