{"timestamp": "2025-09-30 20:26:32", "logger": "infrastructure", "level": "INFO", "file": "cli.py", "line": 32, "function": "main", "message": "Odin CLI initialized"}
{"timestamp": "2025-09-30 20:26:36", "logger": "infrastructure", "level": "INFO", "file": "cli.py", "line": 32, "function": "main", "message": "Odin CLI initialized"}
{"timestamp": "2025-09-30 20:26:40", "logger": "infrastructure", "level": "INFO", "file": "cli.py", "line": 32, "function": "main", "message": "Odin CLI initialized"}
{"timestamp": "2025-09-30 20:26:51", "logger": "infrastructure", "level": "INFO", "file": "cli.py", "line": 32, "function": "main", "message": "Odin CLI initialized"}
{"timestamp": "2025-09-30 20:26:59", "logger": "infrastructure", "level": "INFO", "file": "cli.py", "line": 32, "function": "main", "message": "Odin CLI initialized"}
{"timestamp": "2025-09-30 20:27:08", "logger": "infrastructure", "level": "INFO", "file": "cli.py", "line": 32, "function": "main", "message": "Odin CLI initialized"}
{"timestamp": "2025-09-30 20:27:18", "logger": "infrastructure", "level": "INFO", "file": "cli.py", "line": 32, "function": "main", "message": "Odin CLI initialized"}
{"timestamp": "2025-09-30 20:27:29", "logger": "infrastructure", "level": "INFO", "file": "cli.py", "line": 32, "function": "main", "message": "Odin CLI initialized"}
{"timestamp": "2025-09-30 20:27:29", "logger": "infrastructure", "level": "INFO", "file": "cli.py", "line": 212, "function": "handle_infrastructure_command", "message": "Checking infrastructure status"}
{"timestamp": "2025-09-30 20:27:30", "logger": "infrastructure", "level": "INFO", "file": "cli.py", "line": 215, "function": "handle_infrastructure_command", "message": "Infrastructure status: {'docker': {'status': 'error', 'error': "'NoneType' object has no attribute 'containers'"}, 'localstack': {'status': 'error', 'error': "HTTPConnectionPool(host='localhost', port=4566): Max retries exceeded with url: /health (Caused by NewConnectionError('<urllib3.connection.HTTPConnection object at 0x7dc3853dee40>: Failed to establish a new connection: [Errno 111] Connection refused'))"}, 'minio': {'status': 'error', 'error': "HTTPConnectionPool(host='localhost', port=9000): Max retries exceeded with url: /minio/health/live (Caused by NewConnectionError('<urllib3.connection.HTTPConnection object at 0x7dc38542a490>: Failed to establish a new connection: [Errno 111] Connection refused'))"}, 'redis': {'status': 'error', 'error': 'Error 111 connecting to localhost:6379. Connection refused.'}, 'postgres': {'status': 'error', 'error': "No module named 'psycopg2'"}}"}
{"timestamp": "2025-09-30 20:35:44", "logger": "infrastructure", "level": "INFO", "file": "cli.py", "line": 32, "function": "main", "message": "Odin CLI initialized"}
{"timestamp": "2025-09-30 20:35:44", "logger": "infrastructure", "level": "INFO", "file": "cli.py", "line": 212, "function": "handle_infrastructure_command", "message": "Checking infrastructure status"}
{"timestamp": "2025-09-30 20:35:44", "logger": "infrastructure", "level": "INFO", "file": "cli.py", "line": 215, "function": "handle_infrastructure_command", "message": "Infrastructure status: {'docker': {'status': 'error', 'error': "'NoneType' object has no attribute 'containers'"}, 'localstack': {'status': 'error', 'error': "HTTPConnectionPool(host='localhost', port=4566): Max retries exceeded with url: /health (Caused by NewConnectionError('<urllib3.connection.HTTPConnection object at 0x7b310e5af4d0>: Failed to establish a new connection: [Errno 111] Connection refused'))"}, 'minio': {'status': 'running', 'endpoint': 'http://localhost:9000'}, 'redis': {'status': 'running', 'url': 'redis://localhost:6379'}, 'postgres': {'status': 'error', 'error': "No module named 'psycopg2'"}}"}
{"timestamp": "2025-09-30 20:36:16", "logger": "infrastructure", "level": "INFO", "file": "cli.py", "line": 32, "function": "main", "message": "Odin CLI initialized"}
{"timestamp": "2025-09-30 20:36:16", "logger": "infrastructure", "level": "INFO", "file": "cli.py", "line": 212, "function": "handle_infrastructure_command", "message": "Checking infrastructure status"}
{"timestamp": "2025-09-30 20:36:17", "logger": "infrastructure", "level": "INFO", "file": "cli.py", "line": 215, "function": "handle_infrastructure_command", "message": "Infrastructure status: {'docker': {'status': 'error', 'error': "'NoneType' object has no attribute 'containers'"}, 'localstack': {'status': 'error', 'error': "HTTPConnectionPool(host='localhost', port=4566): Max retries exceeded with url: /health (Caused by NewConnectionError('<urllib3.connection.HTTPConnection object at 0x7412b890ee40>: Failed to establish a new connection: [Errno 111] Connection refused'))"}, 'minio': {'status': 'running', 'endpoint': 'http://localhost:9000'}, 'redis': {'status': 'running', 'url': 'redis://localhost:6379'}, 'postgres': {'status': 'running', 'url': 'postgresql://wildlife:wildlife123@localhost:5432/wildlife'}}"}
{"timestamp": "2025-09-30 20:39:44", "logger": "infrastructure", "level": "INFO", "file": "cli.py", "line": 32, "function": "main", "message": "Odin CLI initialized"}
{"timestamp": "2025-09-30 20:39:44", "logger": "infrastructure", "level": "INFO", "file": "cli.py", "line": 212, "function": "handle_infrastructure_command", "message": "Checking infrastructure status"}
{"timestamp": "2025-09-30 20:39:44", "logger": "infrastructure", "level": "INFO", "file": "cli.py", "line": 215, "function": "handle_infrastructure_command", "message": "Infrastructure status: {'docker': {'status': 'error', 'error': "'NoneType' object has no attribute 'containers'"}, 'localstack': {'status': 'error', 'error': "HTTPConnectionPool(host='localhost', port=4566): Max retries exceeded with url: /health (Caused by NewConnectionError('<urllib3.connection.HTTPConnection object at 0x7de3361f2e40>: Failed to establish a new connection: [Errno 111] Connection refused'))"}, 'minio': {'status': 'error', 'error': "HTTPConnectionPool(host='localhost', port=9000): Max retries exceeded with url: /minio/health/live (Caused by NewConnectionError('<urllib3.connection.HTTPConnection object at 0x7de336246350>: Failed to establish a new connection: [Errno 111] Connection refused'))"}, 'redis': {'status': 'error', 'error': 'Error 111 connecting to localhost:6379. Connection refused.'}, 'postgres': {'status': 'error', 'error': 'connection to server at "localhost" (127.0.0.1), port 5432 failed: Connection refused\n\tIs the server running on that host and accepting TCP/IP connections?\n'}}"}
{"timestamp": "2025-09-30 20:41:15", "logger": "infrastructure", "level": "INFO", "file": "cli.py", "line": 32, "function": "main", "message": "Odin CLI initialized"}
{"timestamp": "2025-09-30 20:41:15", "logger": "infrastructure", "level": "INFO", "file": "cli.py", "line": 212, "function": "handle_infrastructure_command", "message": "Checking infrastructure status"}
{"timestamp": "2025-09-30 20:41:15", "logger": "infrastructure", "level": "INFO", "file": "cli.py", "line": 215, "function": "handle_infrastructure_command", "message": "Infrastructure status: {'docker': {'status': 'error', 'error': "'NoneType' object has no attribute 'containers'"}, 'localstack': {'status': 'error', 'error': "HTTPConnectionPool(host='localhost', port=4566): Max retries exceeded with url: /health (Caused by NewConnectionError('<urllib3.connection.HTTPConnection object at 0x739f107bee40>: Failed to establish a new connection: [Errno 111] Connection refused'))"}, 'minio': {'status': 'error', 'error': "HTTPConnectionPool(host='localhost', port=9000): Max retries exceeded with url: /minio/health/live (Caused by NewConnectionError('<urllib3.connection.HTTPConnection object at 0x739f10812350>: Failed to establish a new connection: [Errno 111] Connection refused'))"}, 'redis': {'status': 'error', 'error': 'Error 111 connecting to localhost:6379. Connection refused.'}, 'postgres': {'status': 'error', 'error': 'connection to server at "localhost" (127.0.0.1), port 5432 failed: Connection refused\n\tIs the server running on that host and accepting TCP/IP connections?\n'}}"}
